Workbook

Sheet جدول الكميات
A1: جدول الكميات التفصيلي
A3: إجمالي قيمة العقد بدون VAT (ريال) | C3: 955036.09 | E3: دليل الألوان: | F3: مدخلات قابلة للتعديل
A4: نسبة ضريبة القيمة المضافة (VAT) | C4: 0.15 | F4: معادلات (لا تُعدَّل)
A6: رقم المخرج الرئيسي | B6: المخرج الرئيسي | C6: نسبة المخرج الرئيسي من المخرجات الرئيسية | D6: المخرج الفرعي | E6: الوحدة | F6: العدد | G6: نسبة التوزيع داخل المخرج الرئيسي | H6: سعر الوحدة | I6: السعر الإجمالي بدون VAT | J6: ="VAT ("&TEXT($C$4,"0%")&")" -> VAT (15%) | K6: الإجمالي مع VAT | L6: السعر كتابةً بالريال السعودي
A7: 1 | B7: حزمة تأسيس المشروع | C7: 0.05 | D7: خطة وميثاق المشروع | E7: وثيقة | F7: 1 | G7: 0.25 | H7: =IF(ISNUMBER(F7),I7/F7,IFERROR("SAR "&TEXT(I7/VALUE(TRIM(MID(F7,FIND("-",F7)+1,20))),"#,##0.00")&" - SAR "&TEXT(I7/VALUE(TRIM(LEFT(F7,FIND("-",F7)-1))),"#,##0.00"),"-")) -> 11937.95 | I7: =ROUND(I$11*G7,2) -> 11937.95 | J7: =ROUND(I7*$C$4,2) -> 1790.69 | K7: =I7+J7 -> 13728.64 | L7: ثلاثة عشر ألفاً وسبعمائة وثمانية وعشرون ريالاً سعودياً وأربع وستون هللة فقط لا غير
D8: خطة إدارة المخاطر | E8: وثيقة | F8: 1 | G8: 0.3 | H8: =IF(ISNUMBER(F8),I8/F8,IFERROR("SAR "&TEXT(I8/VALUE(TRIM(MID(F8,FIND("-",F8)+1,20))),"#,##0.00")&" - SAR "&TEXT(I8/VALUE(TRIM(LEFT(F8,FIND("-",F8)-1))),"#,##0.00"),"-")) -> 14325.54 | I8: =ROUND(I$11*G8,2) -> 14325.54 | J8: =ROUND(I8*$C$4,2) -> 2148.83 | K8: =I8+J8 -> 16474.37 | L8: ستة عشر ألفاً وأربعمائة وأربعة وسبعون ريالاً سعودياً وسبع وثلاثون هللة فقط لا غير
D9: الجدول الزمني للمهام | E9: وثيقة | F9: 1 | G9: 0.1 | H9: =IF(ISNUMBER(F9),I9/F9,IFERROR("SAR "&TEXT(I9/VALUE(TRIM(MID(F9,FIND("-",F9)+1,20))),"#,##0.00")&" - SAR "&TEXT(I9/VALUE(TRIM(LEFT(F9,FIND("-",F9)-1))),"#,##0.00"),"-")) -> 4775.18 | I9: =ROUND(I$11*G9,2) -> 4775.18 | J9: =ROUND(I9*$C$4,2) -> 716.28 | K9: =I9+J9 -> 5491.46 | L9: خمسة آلاف وأربعمائة وواحد وتسعون ريالاً سعودياً وست وأربعون هللة فقط لا غير
D10: خطة إدارة الجودة | E10: وثيقة | F10: 1 | G10: 0.35 | H10: =IF(ISNUMBER(F10),I10/F10,IFERROR("SAR "&TEXT(I10/VALUE(TRIM(MID(F10,FIND("-",F10)+1,20))),"#,##0.00")&" - SAR "&TEXT(I10/VALUE(TRIM(LEFT(F10,FIND("-",F10)-1))),"#,##0.00"),"-")) -> 16713.13 | I10: =I11-SUM(I7:I9) -> 16713.13 | J10: =J11-SUM(J7:J9) -> 2506.97 | K10: =I10+J10 -> 19220.1 | L10: تسعة عشر ألفاً ومائتان وعشرون ريالاً سعودياً وعشر هللات فقط لا غير
D11: إجمالي المخرج الرئيسي (1) | E11: وثيقة | F11: 1 | G11: =SUM(G7:G10) -> 1 | H11: =IF(ISNUMBER(F11),I11/F11,IFERROR("SAR "&TEXT(I11/VALUE(TRIM(MID(F11,FIND("-",F11)+1,20))),"#,##0.00")&" - SAR "&TEXT(I11/VALUE(TRIM(LEFT(F11,FIND("-",F11)-1))),"#,##0.00"),"-")) -> 47751.8 | I11: =ROUND($C$3*C7,2) -> 47751.8 | J11: =ROUND(I11*$C$4,2) -> 7162.77 | K11: =I11+J11 -> 54914.57 | L11: أربعة وخمسون ألفاً وتسعمائة وأربعة عشر ريالاً سعودياً وسبع وخمسون هللة فقط لا غير
A12: 2 | B12: منظومة إدارة المشروع والحوكمة | C12: 0.05 | D12: نظام المتابعة والجدول الموحد ولوحة المؤشرات | E12: لوحة مؤشرات | F12: 1 | G12: 0.7 | H12: =IF(ISNUMBER(F12),I12/F12,IFERROR("SAR "&TEXT(I12/VALUE(TRIM(MID(F12,FIND("-",F12)+1,20))),"#,##0.00")&" - SAR "&TEXT(I12/VALUE(TRIM(LEFT(F12,FIND("-",F12)-1))),"#,##0.00"),"-")) -> 33426.26 | I12: =ROUND(I$14*G12,2) -> 33426.26 | J12: =ROUND(I12*$C$4,2) -> 5013.94 | K12: =I12+J12 -> 38440.2 | L12: ثمانية وثلاثون ألفاً وأربعمائة وأربعون ريالاً سعودياً وعشرون هللة فقط لا غير
D13: مصفوفة الحوكمة والقرارات وخريطة المعالم | E13: لوحة مؤشرات | F13: 1 | G13: 0.3 | H13: =IF(ISNUMBER(F13),I13/F13,IFERROR("SAR "&TEXT(I13/VALUE(TRIM(MID(F13,FIND("-",F13)+1,20))),"#,##0.00")&" - SAR "&TEXT(I13/VALUE(TRIM(LEFT(F13,FIND("-",F13)-1))),"#,##0.00"),"-")) -> 14325.54 | I13: =I14-SUM(I12:I12) -> 14325.54 | J13: =J14-SUM(J12:J12) -> 2148.83 | K13: =I13+J13 -> 16474.37 | L13: ستة عشر ألفاً وأربعمائة وأربعة وسبعون ريالاً سعودياً وسبع وثلاثون هللة فقط لا غير
D14: إجمالي المخرج الرئيسي (2) | E14: لوحة مؤشرات | F14: 1 | G14: =SUM(G12:G13) -> 1 | H14: =IF(ISNUMBER(F14),I14/F14,IFERROR("SAR "&TEXT(I14/VALUE(TRIM(MID(F14,FIND("-",F14)+1,20))),"#,##0.00")&" - SAR "&TEXT(I14/VALUE(TRIM(LEFT(F14,FIND("-",F14)-1))),"#,##0.00"),"-")) -> 47751.8 | I14: =ROUND($C$3*C12,2) -> 47751.8 | J14: =ROUND(I14*$C$4,2) -> 7162.77 | K14: =I14+J14 -> 54914.57 | L14: أربعة وخمسون ألفاً وتسعمائة وأربعة عشر ريالاً سعودياً وسبع وخمسون هللة فقط لا غير
A15: 3 | B15: تقارير التقدم | C15: 0.03 | D15: تقارير التقدّم ومحاضر الاجتماعات | E15: تقارير دورية | F15: 6 | G15: 1 | H15: =IF(ISNUMBER(F15),I15/F15,IFERROR("SAR "&TEXT(I15/VALUE(TRIM(MID(F15,FIND("-",F15)+1,20))),"#,##0.00")&" - SAR "&TEXT(I15/VALUE(TRIM(LEFT(F15,FIND("-",F15)-1))),"#,##0.00"),"-")) -> 4775.18 | I15: =I16 -> 28651.08 | J15: =J16 -> 4297.66 | K15: =I15+J15 -> 32948.74 | L15: اثنان وثلاثون ألفاً وتسعمائة وثمانية وأربعون ريالاً سعودياً وأربع وسبعون هللة فقط لا غير
D16: إجمالي المخرج الرئيسي (3) | E16: تقارير دورية | F16: 6 | G16: =SUM(G15:G15) -> 1 | H16: =IF(ISNUMBER(F16),I16/F16,IFERROR("SAR "&TEXT(I16/VALUE(TRIM(MID(F16,FIND("-",F16)+1,20))),"#,##0.00")&" - SAR "&TEXT(I16/VALUE(TRIM(LEFT(F16,FIND("-",F16)-1))),"#,##0.00"),"-")) -> 4775.18 | I16: =ROUND($C$3*C15,2) -> 28651.08 | J16: =ROUND(I16*$C$4,2) -> 4297.66 | K16: =I16+J16 -> 32948.74 | L16: اثنان وثلاثون ألفاً وتسعمائة وثمانية وأربعون ريالاً سعودياً وأربع وسبعون هللة فقط لا غير
A17: 4 | B17: برنامج الملتقى الفني ومحتواه | C17: 0.18 | D17: البرنامج الفني المزمّن والسيناريو التشغيلي | E17: وثيقة | F17: 1 | G17: 0.1 | H17: =IF(ISNUMBER(F17),I17/F17,IFERROR("SAR "&TEXT(I17/VALUE(TRIM(MID(F17,FIND("-",F17)+1,20))),"#,##0.00")&" - SAR "&TEXT(I17/VALUE(TRIM(LEFT(F17,FIND("-",F17)-1))),"#,##0.00"),"-")) -> 17190.65 | I17: =ROUND(I$21*G17,2) -> 17190.65 | J17: =ROUND(I17*$C$4,2) -> 2578.6 | K17: =I17+J17 -> 19769.25 | L17: تسعة عشر ألفاً وسبعمائة وتسعة وستون ريالاً سعودياً وخمس وعشرون هللة فقط لا غير
D18: الجلسات الحوارية | E18: وثيقة | F18: 1 | G18: 0.35 | H18: =IF(ISNUMBER(F18),I18/F18,IFERROR("SAR "&TEXT(I18/VALUE(TRIM(MID(F18,FIND("-",F18)+1,20))),"#,##0.00")&" - SAR "&TEXT(I18/VALUE(TRIM(LEFT(F18,FIND("-",F18)-1))),"#,##0.00"),"-")) -> 60167.28 | I18: =ROUND(I$21*G18,2) -> 60167.28 | J18: =ROUND(I18*$C$4,2) -> 9025.09 | K18: =I18+J18 -> 69192.37 | L18: تسعة وستون ألفاً ومائة واثنان وتسعون ريالاً سعودياً وسبع وثلاثون هللة فقط لا غير
D19: الورش التفاعلية والنشاط المصاحب | E19: وثيقة | F19: 1 | G19: 0.4 | H19: =IF(ISNUMBER(F19),I19/F19,IFERROR("SAR "&TEXT(I19/VALUE(TRIM(MID(F19,FIND("-",F19)+1,20))),"#,##0.00")&" - SAR "&TEXT(I19/VALUE(TRIM(LEFT(F19,FIND("-",F19)-1))),"#,##0.00"),"-")) -> 68762.6 | I19: =ROUND(I$21*G19,2) -> 68762.6 | J19: =ROUND(I19*$C$4,2) -> 10314.39 | K19: =I19+J19 -> 79076.99 | L19: تسعة وسبعون ألفاً وستة وسبعون ريالاً سعودياً وتسع وتسعون هللة فقط لا غير
D20: تهيئة المتحدثين وملفاتهم وبروفاتهم | E20: وثيقة | F20: 1 | G20: 0.15 | H20: =IF(ISNUMBER(F20),I20/F20,IFERROR("SAR "&TEXT(I20/VALUE(TRIM(MID(F20,FIND("-",F20)+1,20))),"#,##0.00")&" - SAR "&TEXT(I20/VALUE(TRIM(LEFT(F20,FIND("-",F20)-1))),"#,##0.00"),"-")) -> 25785.97 | I20: =I21-SUM(I17:I19) -> 25785.97 | J20: =J21-SUM(J17:J19) -> 3867.9 | K20: =I20+J20 -> 29653.87 | L20: تسعة وعشرون ألفاً وستمائة وثلاثة وخمسون ريالاً سعودياً وسبع وثمانون هللة فقط لا غير
D21: إجمالي المخرج الرئيسي (4) | E21: وثيقة | F21: 1 | G21: =SUM(G17:G20) -> 1 | H21: =IF(ISNUMBER(F21),I21/F21,IFERROR("SAR "&TEXT(I21/VALUE(TRIM(MID(F21,FIND("-",F21)+1,20))),"#,##0.00")&" - SAR "&TEXT(I21/VALUE(TRIM(LEFT(F21,FIND("-",F21)-1))),"#,##0.00"),"-")) -> 171906.5 | I21: =ROUND($C$3*C17,2) -> 171906.5 | J21: =ROUND(I21*$C$4,2) -> 25785.98 | K21: =I21+J21 -> 197692.48 | L21: مائة وسبعة وتسعون ألفاً وستمائة واثنان وتسعون ريالاً سعودياً وثماني وأربعون هللة فقط لا غير
A22: 5 | B22: حزمة الهوية وقوالب المواد | C22: 0.02 | D22: حزمة الهوية وقوالب المواد | E22: حزمة | F22: 1 | G22: 1 | H22: =IF(ISNUMBER(F22),I22/F22,IFERROR("SAR "&TEXT(I22/VALUE(TRIM(MID(F22,FIND("-",F22)+1,20))),"#,##0.00")&" - SAR "&TEXT(I22/VALUE(TRIM(LEFT(F22,FIND("-",F22)-1))),"#,##0.00"),"-")) -> 19100.72 | I22: =I23 -> 19100.72 | J22: =J23 -> 2865.11 | K22: =I22+J22 -> 21965.83 | L22: واحد وعشرون ألفاً وتسعمائة وخمسة وستون ريالاً سعودياً وثلاث وثمانون هللة فقط لا غير
D23: إجمالي المخرج الرئيسي (5) | E23: حزمة | F23: 1 | G23: =SUM(G22:G22) -> 1 | H23: =IF(ISNUMBER(F23),I23/F23,IFERROR("SAR "&TEXT(I23/VALUE(TRIM(MID(F23,FIND("-",F23)+1,20))),"#,##0.00")&" - SAR "&TEXT(I23/VALUE(TRIM(LEFT(F23,FIND("-",F23)-1))),"#,##0.00"),"-")) -> 19100.72 | I23: =ROUND($C$3*C22,2) -> 19100.72 | J23: =ROUND(I23*$C$4,2) -> 2865.11 | K23: =I23+J23 -> 21965.83 | L23: واحد وعشرون ألفاً وتسعمائة وخمسة وستون ريالاً سعودياً وثلاث وثمانون هللة فقط لا غير
A24: 6 | B24: إطار مؤشرات النجاح وقياس أدائها | C24: 0.1 | D24: مؤشرات النجاح ومستهدفاتها وأدوات قياسها | E24: وثيقة | F24: 1 | G24: 1 | H24: =IF(ISNUMBER(F24),I24/F24,IFERROR("SAR "&TEXT(I24/VALUE(TRIM(MID(F24,FIND("-",F24)+1,20))),"#,##0.00")&" - SAR "&TEXT(I24/VALUE(TRIM(LEFT(F24,FIND("-",F24)-1))),"#,##0.00"),"-")) -> 95503.61 | I24: =I25 -> 95503.61 | J24: =J25 -> 14325.54 | K24: =I24+J24 -> 109829.15 | L24: مائة وتسعة آلاف وثمانمائة وتسعة وعشرون ريالاً سعودياً وخمس عشرة هللة فقط لا غير
D25: إجمالي المخرج الرئيسي (6) | E25: وثيقة | F25: 1 | G25: =SUM(G24:G24) -> 1 | H25: =IF(ISNUMBER(F25),I25/F25,IFERROR("SAR "&TEXT(I25/VALUE(TRIM(MID(F25,FIND("-",F25)+1,20))),"#,##0.00")&" - SAR "&TEXT(I25/VALUE(TRIM(LEFT(F25,FIND("-",F25)-1))),"#,##0.00"),"-")) -> 95503.61 | I25: =ROUND($C$3*C24,2) -> 95503.61 | J25: =ROUND(I25*$C$4,2) -> 14325.54 | K25: =I25+J25 -> 109829.15 | L25: مائة وتسعة آلاف وثمانمائة وتسعة وعشرون ريالاً سعودياً وخمس عشرة هللة فقط لا غير
A26: 7 | B26: قاعدة بيانات المشاركين | C26: 0.05 | D26: قاعدة بيانات الشركات والخبراء والمدعوين | E26: قاعدة بيانات | F26: 1 | G26: 1 | H26: =IF(ISNUMBER(F26),I26/F26,IFERROR("SAR "&TEXT(I26/VALUE(TRIM(MID(F26,FIND("-",F26)+1,20))),"#,##0.00")&" - SAR "&TEXT(I26/VALUE(TRIM(LEFT(F26,FIND("-",F26)-1))),"#,##0.00"),"-")) -> 47751.8 | I26: =I27 -> 47751.8 | J26: =J27 -> 7162.77 | K26: =I26+J26 -> 54914.57 | L26: أربعة وخمسون ألفاً وتسعمائة وأربعة عشر ريالاً سعودياً وسبع وخمسون هللة فقط لا غير
D27: إجمالي المخرج الرئيسي (7) | E27: قاعدة بيانات | F27: 1 | G27: =SUM(G26:G26) -> 1 | H27: =IF(ISNUMBER(F27),I27/F27,IFERROR("SAR "&TEXT(I27/VALUE(TRIM(MID(F27,FIND("-",F27)+1,20))),"#,##0.00")&" - SAR "&TEXT(I27/VALUE(TRIM(LEFT(F27,FIND("-",F27)-1))),"#,##0.00"),"-")) -> 47751.8 | I27: =ROUND($C$3*C26,2) -> 47751.8 | J27: =ROUND(I27*$C$4,2) -> 7162.77 | K27: =I27+J27 -> 54914.57 | L27: أربعة وخمسون ألفاً وتسعمائة وأربعة عشر ريالاً سعودياً وسبع وخمسون هللة فقط لا غير
A28: 8 | B28: التسجيل والاستقبال | C28: 0.107 | D28: نموذج التسجيل الإلكتروني وتشغيله | E28: نموذج التسجيل | F28: 1 | G28: =1/2 -> 0.5 | H28: =IF(ISNUMBER(F28),I28/F28,IFERROR("SAR "&TEXT(I28/VALUE(TRIM(MID(F28,FIND("-",F28)+1,20))),"#,##0.00")&" - SAR "&TEXT(I28/VALUE(TRIM(LEFT(F28,FIND("-",F28)-1))),"#,##0.00"),"-")) -> 51094.43 | I28: =ROUND(I$30*G28,2) -> 51094.43 | J28: =ROUND(I28*$C$4,2) -> 7664.16 | K28: =I28+J28 -> 58758.59 | L28: ثمانية وخمسون ألفاً وسبعمائة وثمانية وخمسون ريالاً سعودياً وتسع وخمسون هللة فقط لا غير
D29: بطاقات المشاركين وتشغيل الاستقبال | E29: بطاقة | F29: 220 | G29: =1/2 -> 0.5 | H29: =IF(ISNUMBER(F29),I29/F29,IFERROR("SAR "&TEXT(I29/VALUE(TRIM(MID(F29,FIND("-",F29)+1,20))),"#,##0.00")&" - SAR "&TEXT(I29/VALUE(TRIM(LEFT(F29,FIND("-",F29)-1))),"#,##0.00"),"-")) -> 232.24741 | I29: =I30-SUM(I28:I28) -> 51094.43 | J29: =J30-SUM(J28:J28) -> 7664.17 | K29: =I29+J29 -> 58758.6 | L29: ثمانية وخمسون ألفاً وسبعمائة وثمانية وخمسون ريالاً سعودياً وستون هللة فقط لا غير
D30: إجمالي المخرج الرئيسي (8) | E30: نموذج التسجيل | F30: 1 | G30: =SUM(G28:G29) -> 1 | H30: =IF(ISNUMBER(F30),I30/F30,IFERROR("SAR "&TEXT(I30/VALUE(TRIM(MID(F30,FIND("-",F30)+1,20))),"#,##0.00")&" - SAR "&TEXT(I30/VALUE(TRIM(LEFT(F30,FIND("-",F30)-1))),"#,##0.00"),"-")) -> 102188.86 | I30: =ROUND($C$3*C28,2) -> 102188.86 | J30: =ROUND(I30*$C$4,2) -> 15328.33 | K30: =I30+J30 -> 117517.19 | L30: مائة وسبعة عشر ألفاً وخمسمائة وسبعة عشر ريالاً سعودياً وتسع عشرة هللة فقط لا غير
A31: 9 | B31: تخطيط الحملة الإعلامية | C31: 0.02 | D31: الخطة الإعلامية التوعوية | E31: وثيقة | F31: 1 | G31: 1 | H31: =IF(ISNUMBER(F31),I31/F31,IFERROR("SAR "&TEXT(I31/VALUE(TRIM(MID(F31,FIND("-",F31)+1,20))),"#,##0.00")&" - SAR "&TEXT(I31/VALUE(TRIM(LEFT(F31,FIND("-",F31)-1))),"#,##0.00"),"-")) -> 19100.72 | I31: =I32 -> 19100.72 | J31: =J32 -> 2865.11 | K31: =I31+J31 -> 21965.83 | L31: واحد وعشرون ألفاً وتسعمائة وخمسة وستون ريالاً سعودياً وثلاث وثمانون هللة فقط لا غير
D32: إجمالي المخرج الرئيسي (9) | E32: وثيقة | F32: 1 | G32: =SUM(G31:G31) -> 1 | H32: =IF(ISNUMBER(F32),I32/F32,IFERROR("SAR "&TEXT(I32/VALUE(TRIM(MID(F32,FIND("-",F32)+1,20))),"#,##0.00")&" - SAR "&TEXT(I32/VALUE(TRIM(LEFT(F32,FIND("-",F32)-1))),"#,##0.00"),"-")) -> 19100.72 | I32: =ROUND($C$3*C31,2) -> 19100.72 | J32: =ROUND(I32*$C$4,2) -> 2865.11 | K32: =I32+J32 -> 21965.83 | L32: واحد وعشرون ألفاً وتسعمائة وخمسة وستون ريالاً سعودياً وثلاث وثمانون هللة فقط لا غير
A33: 10 | B33: تنفيذ الحملة الإعلامية | C33: 0.06 | D33: المرحلة الأولى (الفيديوهات) | E33: فيديوهات | F33: 1 | G33: 0.45 | H33: =IF(ISNUMBER(F33),I33/F33,IFERROR("SAR "&TEXT(I33/VALUE(TRIM(MID(F33,FIND("-",F33)+1,20))),"#,##0.00")&" - SAR "&TEXT(I33/VALUE(TRIM(LEFT(F33,FIND("-",F33)-1))),"#,##0.00"),"-")) -> 25785.98 | I33: =ROUND(I$36*G33,2) -> 25785.98 | J33: =ROUND(I33*$C$4,2) -> 3867.9 | K33: =I33+J33 -> 29653.88 | L33: تسعة وعشرون ألفاً وستمائة وثلاثة وخمسون ريالاً سعودياً وثماني وثمانون هللة فقط لا غير
D34: المرحلة الأولى (الإنفوجراف) | E34: إنفوجراف | F34: 3 | G34: 0.25 | H34: =IF(ISNUMBER(F34),I34/F34,IFERROR("SAR "&TEXT(I34/VALUE(TRIM(MID(F34,FIND("-",F34)+1,20))),"#,##0.00")&" - SAR "&TEXT(I34/VALUE(TRIM(LEFT(F34,FIND("-",F34)-1))),"#,##0.00"),"-")) -> 4775.18 | I34: =ROUND(I$36*G34,2) -> 14325.54 | J34: =ROUND(I34*$C$4,2) -> 2148.83 | K34: =I34+J34 -> 16474.37 | L34: ستة عشر ألفاً وأربعمائة وأربعة وسبعون ريالاً سعودياً وسبع وثلاثون هللة فقط لا غير
D35: المرحلة الثانية | E35: فيديوهات | F35: 1 | G35: 0.3 | H35: =IF(ISNUMBER(F35),I35/F35,IFERROR("SAR "&TEXT(I35/VALUE(TRIM(MID(F35,FIND("-",F35)+1,20))),"#,##0.00")&" - SAR "&TEXT(I35/VALUE(TRIM(LEFT(F35,FIND("-",F35)-1))),"#,##0.00"),"-")) -> 17190.65 | I35: =I36-SUM(I33:I34) -> 17190.65 | J35: =J36-SUM(J33:J34) -> 2578.6 | K35: =I35+J35 -> 19769.25 | L35: تسعة عشر ألفاً وسبعمائة وتسعة وستون ريالاً سعودياً وخمس وعشرون هللة فقط لا غير
D36: إجمالي المخرج الرئيسي (10) | E36: مواد إعلامية | F36: 5 | G36: =SUM(G33:G35) -> 1 | H36: =IF(ISNUMBER(F36),I36/F36,IFERROR("SAR "&TEXT(I36/VALUE(TRIM(MID(F36,FIND("-",F36)+1,20))),"#,##0.00")&" - SAR "&TEXT(I36/VALUE(TRIM(LEFT(F36,FIND("-",F36)-1))),"#,##0.00"),"-")) -> 11460.434 | I36: =ROUND($C$3*C33,2) -> 57302.17 | J36: =ROUND(I36*$C$4,2) -> 8595.33 | K36: =I36+J36 -> 65897.5 | L36: خمسة وستون ألفاً وثمانمائة وسبعة وتسعون ريالاً سعودياً وخمسون هللة فقط لا غير
A37: 11 | B37: الجاهزية التشغيلية وتنفيذ يوم الملتقى | C37: 0.273 | D37: ضوابط الهوية وتجربة الزائر للمعرض، ونماذج مطابقة مخرجات المورد | E37: وثيقة | F37: 1 | G37: 0.25 | H37: =IF(ISNUMBER(F37),I37/F37,IFERROR("SAR "&TEXT(I37/VALUE(TRIM(MID(F37,FIND("-",F37)+1,20))),"#,##0.00")&" - SAR "&TEXT(I37/VALUE(TRIM(LEFT(F37,FIND("-",F37)-1))),"#,##0.00"),"-")) -> 65181.21 | I37: =ROUND(I$41*G37,2) -> 65181.21 | J37: =ROUND(I37*$C$4,2) -> 9777.18 | K37: =I37+J37 -> 74958.39 | L37: أربعة وسبعون ألفاً وتسعمائة وثمانية وخمسون ريالاً سعودياً وتسع وثلاثون هللة فقط لا غير
D38: إدارة الأعمال المؤقّرة والمورد الموجّه | E38: وثيقة | F38: 1 | G38: 0.35 | H38: =IF(ISNUMBER(F38),I38/F38,IFERROR("SAR "&TEXT(I38/VALUE(TRIM(MID(F38,FIND("-",F38)+1,20))),"#,##0.00")&" - SAR "&TEXT(I38/VALUE(TRIM(LEFT(F38,FIND("-",F38)-1))),"#,##0.00"),"-")) -> 91253.7 | I38: =ROUND(I$41*G38,2) -> 91253.7 | J38: =ROUND(I38*$C$4,2) -> 13688.06 | K38: =I38+J38 -> 104941.76 | L38: مائة وأربعة آلاف وتسعمائة وواحد وأربعون ريالاً سعودياً وست وسبعون هللة فقط لا غير
D39: التغطية الإعلامية يوم الملتقى | E39: تغطية بصرية | F39: 1 | G39: 0.15 | H39: =IF(ISNUMBER(F39),I39/F39,IFERROR("SAR "&TEXT(I39/VALUE(TRIM(MID(F39,FIND("-",F39)+1,20))),"#,##0.00")&" - SAR "&TEXT(I39/VALUE(TRIM(LEFT(F39,FIND("-",F39)-1))),"#,##0.00"),"-")) -> 39108.73 | I39: =ROUND(I$41*G39,2) -> 39108.73 | J39: =ROUND(I39*$C$4,2) -> 5866.31 | K39: =I39+J39 -> 44975.04 | L39: أربعة وأربعون ألفاً وتسعمائة وخمسة وسبعون ريالاً سعودياً وأربع هللات فقط لا غير
D40: حزمة الإنتاج والمطبوعات | E40: حزمة | F40: 1 | G40: 0.25 | H40: =IF(ISNUMBER(F40),I40/F40,IFERROR("SAR "&TEXT(I40/VALUE(TRIM(MID(F40,FIND("-",F40)+1,20))),"#,##0.00")&" - SAR "&TEXT(I40/VALUE(TRIM(LEFT(F40,FIND("-",F40)-1))),"#,##0.00"),"-")) -> 65181.21 | I40: =I41-SUM(I37:I39) -> 65181.21 | J40: =J41-SUM(J37:J39) -> 9777.18 | K40: =I40+J40 -> 74958.39 | L40: أربعة وسبعون ألفاً وتسعمائة وثمانية وخمسون ريالاً سعودياً وتسع وثلاثون هللة فقط لا غير
D41: إجمالي المخرج الرئيسي (11) | E41: دعم تشغيلي | F41: 1 | G41: =SUM(G37:G40) -> 1 | H41: =IF(ISNUMBER(F41),I41/F41,IFERROR("SAR "&TEXT(I41/VALUE(TRIM(MID(F41,FIND("-",F41)+1,20))),"#,##0.00")&" - SAR "&TEXT(I41/VALUE(TRIM(LEFT(F41,FIND("-",F41)-1))),"#,##0.00"),"-")) -> 260724.85 | I41: =ROUND($C$3*C37,2) -> 260724.85 | J41: =ROUND(I41*$C$4,2) -> 39108.73 | K41: =I41+J41 -> 299833.58 | L41: مائتان وتسعة وتسعون ألفاً وثمانمائة وثلاثة وثلاثون ريالاً سعودياً وثماني وخمسون هللة فقط لا غير
A42: 12 | B42: الإغلاق وقياس الأثر | C42: 0.06 | D42: التقرير الختامي والتوثيق | E42: وثيقة | F42: 1 | G42: 0.35 | H42: =IF(ISNUMBER(F42),I42/F42,IFERROR("SAR "&TEXT(I42/VALUE(TRIM(MID(F42,FIND("-",F42)+1,20))),"#,##0.00")&" - SAR "&TEXT(I42/VALUE(TRIM(LEFT(F42,FIND("-",F42)-1))),"#,##0.00"),"-")) -> 20055.76 | I42: =ROUND(I$45*G42,2) -> 20055.76 | J42: =ROUND(I42*$C$4,2) -> 3008.36 | K42: =I42+J42 -> 23064.12 | L42: ثلاثة وعشرون ألفاً وأربعة وستون ريالاً سعودياً واثنتا عشرة هللة فقط لا غير
...

Sheet مقارنة التخفيض
A1: مقارنة العرض المالي قبل التخفيض وبعده
A3: إجمالي العرض السابق بدون VAT (ريال) | C3: 1041992.6
A5: م | B5: المخرج الرئيسي | C5: النسبة السابقة | D5: السعر السابق بدون VAT | E5: النسبة الجديدة | F5: السعر الجديد بدون VAT | G5: الفرق | H5: نسبة التغيّر
A6: 1 | B6: حزمة تأسيس المشروع | C6: 0.05 | D6: =ROUND($C$3*C6,2) -> 52099.63 | E6: ='جدول الكميات'!C7 -> 0.05 | F6: ='جدول الكميات'!I11 -> 47751.8 | G6: =F6-D6 -> -4347.83 | H6: =IF(D6=0,0,G6/D6) -> -0.083452224
A7: 2 | B7: منظومة إدارة المشروع والحوكمة | C7: 0.06 | D7: =ROUND($C$3*C7,2) -> 62519.56 | E7: ='جدول الكميات'!C12 -> 0.05 | F7: ='جدول الكميات'!I14 -> 47751.8 | G7: =F7-D7 -> -14767.76 | H7: =IF(D7=0,0,G7/D7) -> -0.23621024
A8: 3 | B8: تقارير التقدم | C8: 0.03 | D8: =ROUND($C$3*C8,2) -> 31259.78 | E8: ='جدول الكميات'!C15 -> 0.03 | F8: ='جدول الكميات'!I16 -> 28651.08 | G8: =F8-D8 -> -2608.7 | H8: =IF(D8=0,0,G8/D8) -> -0.083452283
A9: 4 | B9: برنامج الملتقى الفني ومحتواه | C9: 0.14 | D9: =ROUND($C$3*C9,2) -> 145878.97 | E9: ='جدول الكميات'!C17 -> 0.18 | F9: ='جدول الكميات'!I21 -> 171906.5 | G9: =F9-D9 -> 26027.53 | H9: =IF(D9=0,0,G9/D9) -> 0.17841866
A10: 5 | B10: حزمة الهوية وقوالب المواد | C10: 0.02 | D10: =ROUND($C$3*C10,2) -> 20839.85 | E10: ='جدول الكميات'!C22 -> 0.02 | F10: ='جدول الكميات'!I23 -> 19100.72 | G10: =F10-D10 -> -1739.13 | H10: =IF(D10=0,0,G10/D10) -> -0.083452136
A11: 6 | B11: إطار مؤشرات النجاح وقياس أدائها | C11: 0.1 | D11: =ROUND($C$3*C11,2) -> 104199.26 | E11: ='جدول الكميات'!C24 -> 0.1 | F11: ='جدول الكميات'!I25 -> 95503.61 | G11: =F11-D11 -> -8695.65 | H11: =IF(D11=0,0,G11/D11) -> -0.083452128
A12: 7 | B12: قاعدة بيانات المشاركين | C12: 0.02 | D12: =ROUND($C$3*C12,2) -> 20839.85 | E12: ='جدول الكميات'!C26 -> 0.05 | F12: ='جدول الكميات'!I27 -> 47751.8 | G12: =F12-D12 -> 26911.95 | H12: =IF(D12=0,0,G12/D12) -> 1.2913697
A13: 8 | B13: التسجيل والاستقبال | C13: 0.1 | D13: =ROUND($C$3*C13,2) -> 104199.26 | E13: ='جدول الكميات'!C28 -> 0.107 | F13: ='جدول الكميات'!I30 -> 102188.86 | G13: =F13-D13 -> -2010.4 | H13: =IF(D13=0,0,G13/D13) -> -0.019293803
A14: 9 | B14: تخطيط الحملة الإعلامية | C14: 0.07 | D14: =ROUND($C$3*C14,2) -> 72939.48 | E14: ='جدول الكميات'!C31 -> 0.02 | F14: ='جدول الكميات'!I32 -> 19100.72 | G14: =F14-D14 -> -53838.76 | H14: =IF(D14=0,0,G14/D14) -> -0.7381292
A15: 10 | B15: تنفيذ الحملة الإعلامية | C15: 0.15 | D15: =ROUND($C$3*C15,2) -> 156298.89 | E15: ='جدول الكميات'!C33 -> 0.06 | F15: ='جدول الكميات'!I36 -> 57302.17 | G15: =F15-D15 -> -98996.72 | H15: =IF(D15=0,0,G15/D15) -> -0.63338083
A16: 11 | B16: الجاهزية التشغيلية وتنفيذ يوم الملتقى | C16: 0.2 | D16: =ROUND($C$3*C16,2) -> 208398.52 | E16: ='جدول الكميات'!C37 -> 0.273 | F16: ='جدول الكميات'!I41 -> 260724.85 | G16: =F16-D16 -> 52326.33 | H16: =IF(D16=0,0,G16/D16) -> 0.25108782
A17: 12 | B17: الإغلاق وقياس الأثر | C17: 0.06 | D17: =ROUND($C$3*C17,2) -> 62519.56 | E17: ='جدول الكميات'!C42 -> 0.06 | F17: ='جدول الكميات'!I45 -> 57302.17 | G17: =F17-D17 -> -5217.39 | H17: =IF(D17=0,0,G17/D17) -> -0.083452123
A18: الإجمالي بدون VAT | C18: =SUM(C6:C17) -> 1 | D18: =SUM(D6:D17) -> 1041992.6 | E18: =SUM(E6:E17) -> 1 | F18: =SUM(F6:F17) -> 955036.08 | G18: =SUM(G6:G17) -> -86956.53 | H18: =IF(D18=0,0,G18/D18) -> -0.083452156
A19: VAT | D19: =SUMPRODUCT(ROUND(D6:D17*'جدول الكميات'!$C$4,2)) -> 156298.89 | F19: ='جدول الكميات'!J46 -> 143255.43 | G19: =F19-D19 -> -13043.46 | H19: =IF(D19=0,0,G19/D19) -> -0.083452032
A20: الإجمالي مع VAT | D20: =D18+D19 -> 1198291.5 | F20: ='جدول الكميات'!K46 -> 1098291.5 | G20: =F20-D20 -> -99999.99 | H20: =IF(D20=0,0,G20/D20) -> -0.08345214
A22: ملاحظات:
A23: • البندان الملوّنان بالبرتقالي (الحملة الإعلامية) يتركّز فيهما التخفيض، والبند الملوّن بالأخضر (11) تمت زيادته لبيان الجهد التنفيذي.
A24: • النسبة الجديدة والسعر الجديد (بالأخضر) مربوطان بشيت (جدول الكميات)؛ أي تعديل هناك ينعكس هنا تلقائياً.
A25: • داخل المخرج 11 رُفع وزن (إدارة الأعمال والمورد الموجّه) إلى 35% وخُفّض وزن (التغطية الإعلامية) إلى 15%.
